2025-10-28 17:15:31,954 INFO    MainThread:2427096 [wandb_setup.py:_flush():81] Current SDK version is 0.22.2
2025-10-28 17:15:31,954 INFO    MainThread:2427096 [wandb_setup.py:_flush():81] Configure stats pid to 2427096
2025-10-28 17:15:31,954 INFO    MainThread:2427096 [wandb_setup.py:_flush():81] Loading settings from /home/zs7752/.config/wandb/settings
2025-10-28 17:15:31,954 INFO    MainThread:2427096 [wandb_setup.py:_flush():81] Loading settings from /ssd1/zhizhou/workspace/simple_GRPO/wandb/settings
2025-10-28 17:15:31,954 INFO    MainThread:2427096 [wandb_setup.py:_flush():81] Loading settings from environment variables
2025-10-28 17:15:31,954 INFO    MainThread:2427096 [wandb_init.py:setup_run_log_directory():705] Logging user logs to /ssd1/zhizhou/workspace/simple_GRPO/wandb/run-20251028_171531-h04rkl0w/logs/debug.log
2025-10-28 17:15:31,954 INFO    MainThread:2427096 [wandb_init.py:setup_run_log_directory():706] Logging internal logs to /ssd1/zhizhou/workspace/simple_GRPO/wandb/run-20251028_171531-h04rkl0w/logs/debug-internal.log
2025-10-28 17:15:31,954 INFO    MainThread:2427096 [wandb_init.py:init():832] calling init triggers
2025-10-28 17:15:31,954 INFO    MainThread:2427096 [wandb_init.py:init():837] wandb.init called with sweep_config: {}
config: {'model_path': 'Qwen/Qwen3-0.6B', 'beta': 0.01, 'all_steps': 1000, 'Q_batch_size': 5, 'num_samples_per_prompt': 8, 'train_batch_size': 8, 'clip_param': 0.2, 'learning_rate': 1e-06, 'gradient_accumulation_steps': 4, 'temperature': 0.9, 'max_new_tokens': 1024, 'use_bf16': False, '_wandb': {}}
2025-10-28 17:15:31,954 INFO    MainThread:2427096 [wandb_init.py:init():880] starting backend
2025-10-28 17:15:32,160 INFO    MainThread:2427096 [wandb_init.py:init():883] sending inform_init request
2025-10-28 17:15:32,167 INFO    MainThread:2427096 [wandb_init.py:init():891] backend started and connected
2025-10-28 17:15:32,169 INFO    MainThread:2427096 [wandb_init.py:init():961] updated telemetry
2025-10-28 17:15:32,177 INFO    MainThread:2427096 [wandb_init.py:init():985] communicating run to backend with 90.0 second timeout
2025-10-28 17:15:32,694 INFO    MainThread:2427096 [wandb_init.py:init():1036] starting run threads in backend
2025-10-28 17:15:32,872 INFO    MainThread:2427096 [wandb_run.py:_console_start():2509] atexit reg
2025-10-28 17:15:32,872 INFO    MainThread:2427096 [wandb_run.py:_redirect():2357] redirect: wrap_raw
2025-10-28 17:15:32,872 INFO    MainThread:2427096 [wandb_run.py:_redirect():2426] Wrapping output streams.
2025-10-28 17:15:32,872 INFO    MainThread:2427096 [wandb_run.py:_redirect():2449] Redirects installed.
2025-10-28 17:15:32,875 INFO    MainThread:2427096 [wandb_init.py:init():1076] run started, returning control to user process
2025-10-28 17:17:51,026 INFO    wandb-AsyncioManager-main:2427096 [service_client.py:_forward_responses():80] Reached EOF.
2025-10-28 17:17:51,026 INFO    wandb-AsyncioManager-main:2427096 [mailbox.py:close():137] Closing mailbox, abandoning 1 handles.
2025-10-28 17:17:51,538 ERROR   MainThread:2427096 [redirect.py:_on_write():664] [all runs] error in stderr callback
Traceback (most recent call last):
  File "/home/zs7752/miniconda3/envs/trl/lib/python3.12/site-packages/wandb/sdk/lib/redirect.py", line 662, in _on_write
    cb(written_data)
  File "/home/zs7752/miniconda3/envs/trl/lib/python3.12/site-packages/wandb/sdk/wandb_run.py", line 2436, in <lambda>
    lambda data: self._console_raw_callback("stderr", data),
                 ^^^^^^^^^^^^^^^^^^^^^^^^^^^^^^^^^^^^^^^^^^
  File "/home/zs7752/miniconda3/envs/trl/lib/python3.12/site-packages/wandb/sdk/wandb_run.py", line 399, in wrapper
    return func(self, *args, **kwargs)
           ^^^^^^^^^^^^^^^^^^^^^^^^^^^
  File "/home/zs7752/miniconda3/envs/trl/lib/python3.12/site-packages/wandb/sdk/wandb_run.py", line 457, in wrapper_fn
    return func(self, *args, **kwargs)
           ^^^^^^^^^^^^^^^^^^^^^^^^^^^
  File "/home/zs7752/miniconda3/envs/trl/lib/python3.12/site-packages/wandb/sdk/wandb_run.py", line 1595, in _console_raw_callback
    self._backend.interface.publish_output_raw(name, data)
  File "/home/zs7752/miniconda3/envs/trl/lib/python3.12/site-packages/wandb/sdk/interface/interface.py", line 802, in publish_output_raw
    self._publish_output_raw(o)
  File "/home/zs7752/miniconda3/envs/trl/lib/python3.12/site-packages/wandb/sdk/interface/interface_shared.py", line 37, in _publish_output_raw
    self._publish(rec)
  File "/home/zs7752/miniconda3/envs/trl/lib/python3.12/site-packages/wandb/sdk/interface/interface_sock.py", line 43, in _publish
    self._asyncer.run(lambda: self._client.publish(request))
  File "/home/zs7752/miniconda3/envs/trl/lib/python3.12/site-packages/wandb/sdk/lib/asyncio_manager.py", line 136, in run
    return future.result()
           ^^^^^^^^^^^^^^^
  File "/home/zs7752/miniconda3/envs/trl/lib/python3.12/concurrent/futures/_base.py", line 456, in result
    return self.__get_result()
           ^^^^^^^^^^^^^^^^^^^
  File "/home/zs7752/miniconda3/envs/trl/lib/python3.12/concurrent/futures/_base.py", line 401, in __get_result
    raise self._exception
  File "/home/zs7752/miniconda3/envs/trl/lib/python3.12/site-packages/wandb/sdk/lib/asyncio_manager.py", line 219, in _wrap
    return await fn()
           ^^^^^^^^^^
  File "/home/zs7752/miniconda3/envs/trl/lib/python3.12/site-packages/wandb/sdk/lib/service/service_client.py", line 38, in publish
    await self._send_server_request(request)
  File "/home/zs7752/miniconda3/envs/trl/lib/python3.12/site-packages/wandb/sdk/lib/service/service_client.py", line 64, in _send_server_request
    await self._writer.drain()
  File "/home/zs7752/miniconda3/envs/trl/lib/python3.12/asyncio/streams.py", line 392, in drain
    await self._protocol._drain_helper()
  File "/home/zs7752/miniconda3/envs/trl/lib/python3.12/asyncio/streams.py", line 166, in _drain_helper
    raise ConnectionResetError('Connection lost')
ConnectionResetError: Connection lost
2025-10-28 17:17:51,543 ERROR   MainThread:2427096 [redirect.py:_on_write():664] [all runs] error in stderr callback
Traceback (most recent call last):
  File "/home/zs7752/miniconda3/envs/trl/lib/python3.12/site-packages/wandb/sdk/lib/redirect.py", line 662, in _on_write
    cb(written_data)
  File "/home/zs7752/miniconda3/envs/trl/lib/python3.12/site-packages/wandb/sdk/wandb_run.py", line 2436, in <lambda>
    lambda data: self._console_raw_callback("stderr", data),
                 ^^^^^^^^^^^^^^^^^^^^^^^^^^^^^^^^^^^^^^^^^^
  File "/home/zs7752/miniconda3/envs/trl/lib/python3.12/site-packages/wandb/sdk/wandb_run.py", line 399, in wrapper
    return func(self, *args, **kwargs)
           ^^^^^^^^^^^^^^^^^^^^^^^^^^^
  File "/home/zs7752/miniconda3/envs/trl/lib/python3.12/site-packages/wandb/sdk/wandb_run.py", line 457, in wrapper_fn
    return func(self, *args, **kwargs)
           ^^^^^^^^^^^^^^^^^^^^^^^^^^^
  File "/home/zs7752/miniconda3/envs/trl/lib/python3.12/site-packages/wandb/sdk/wandb_run.py", line 1595, in _console_raw_callback
    self._backend.interface.publish_output_raw(name, data)
  File "/home/zs7752/miniconda3/envs/trl/lib/python3.12/site-packages/wandb/sdk/interface/interface.py", line 802, in publish_output_raw
    self._publish_output_raw(o)
  File "/home/zs7752/miniconda3/envs/trl/lib/python3.12/site-packages/wandb/sdk/interface/interface_shared.py", line 37, in _publish_output_raw
    self._publish(rec)
  File "/home/zs7752/miniconda3/envs/trl/lib/python3.12/site-packages/wandb/sdk/interface/interface_sock.py", line 43, in _publish
    self._asyncer.run(lambda: self._client.publish(request))
  File "/home/zs7752/miniconda3/envs/trl/lib/python3.12/site-packages/wandb/sdk/lib/asyncio_manager.py", line 136, in run
    return future.result()
           ^^^^^^^^^^^^^^^
  File "/home/zs7752/miniconda3/envs/trl/lib/python3.12/concurrent/futures/_base.py", line 456, in result
    return self.__get_result()
           ^^^^^^^^^^^^^^^^^^^
  File "/home/zs7752/miniconda3/envs/trl/lib/python3.12/concurrent/futures/_base.py", line 401, in __get_result
    raise self._exception
  File "/home/zs7752/miniconda3/envs/trl/lib/python3.12/site-packages/wandb/sdk/lib/asyncio_manager.py", line 219, in _wrap
    return await fn()
           ^^^^^^^^^^
  File "/home/zs7752/miniconda3/envs/trl/lib/python3.12/site-packages/wandb/sdk/lib/service/service_client.py", line 38, in publish
    await self._send_server_request(request)
  File "/home/zs7752/miniconda3/envs/trl/lib/python3.12/site-packages/wandb/sdk/lib/service/service_client.py", line 64, in _send_server_request
    await self._writer.drain()
  File "/home/zs7752/miniconda3/envs/trl/lib/python3.12/asyncio/streams.py", line 392, in drain
    await self._protocol._drain_helper()
  File "/home/zs7752/miniconda3/envs/trl/lib/python3.12/asyncio/streams.py", line 166, in _drain_helper
    raise ConnectionResetError('Connection lost')
ConnectionResetError: Connection lost
